<?xml version="1.0"?>
<robot name="bluecar">
<!-- /////////////////////////////////////    COLOR    ///////////////////////////////////////////// -->
<material name="blue">
    <color rgba="0 0 0.8 1"/>
</material>
   
<material name="white">
    <color rgba="1 1 1 1"/>
 </material>

<material name="Black">
    <color rgba="0 0 0 1"/>
</material>

<material name="Yellow">
    <color rgba="1 0.4 0 1"/>
</material>

  <link name="base_footprint">
      <visual>
          <geometry>
              <sphere radius="0.001" />
          </geometry>
      </visual>
  </link>


  <link name="base_link">
    <visual>
      <origin xyz="0.0 0.0 0.05" rpy="0.0 0.0 0.0"/>
      
      <geometry>
        <box size="0.305 0.143 0.15"/>
      </geometry>
      <material name="blue"/>
    </visual>
  </link>

  <joint name="base_link2base_footprint" type="fixed">
      <parent link="base_footprint" />
      <child link="base_link" />
      <origin xyz="0 0 0.05" />
  </joint>

  <link name="front_leftwheel">
    <visual>
    <origin xyz="0 0.0 0.0" rpy="1.5707 0 0"/>
      <geometry>
        <cylinder length="0.04" radius="0.05"/>
      </geometry>
      <material name="Black"/>

    </visual>
  </link>
 
  <joint name="front_leftwheel_joint" type="continuous">
    <origin xyz="0.09 0.0915 0.0" rpy="0 0 0"/>
    <parent link="base_link"/>
     <child link="front_leftwheel"/>
     <axis xyz="0 1 0"/>
  </joint>



  <link name="front_rightwheel">
    <visual>
    <origin xyz="0 0.0 0.0" rpy="1.5707 0 0"/>
      <geometry>
        <cylinder length="0.04" radius="0.05"/>
      </geometry>
      <material name="Black"/>

    </visual>
  </link>
 
  <joint name="front_rightwheel_joint" type="continuous">
    <origin xyz="0.09 -0.0915 0.0" rpy="0 0 0"/>
    <parent link="base_link"/>
     <child link="front_rightwheel"/>
     <axis xyz="0 1 0"/>
  </joint>  

<!-- /////////////////////////////////////    LASER    ///////////////////////////////////////////// -->
    <link name="laser_link">
		<visual>
			<origin xyz=" 0 0 0 " rpy="0 0 0" />
			<geometry>
				<cylinder length="0.05" radius="0.05"/>
			</geometry>
			<material name="Black"/>
		</visual>
    </link>

    <joint name="laser_joint" type="fixed">
        <origin xyz="0.09 0 0.20" rpy="0 0 3.1416"/>
        <parent link="base_link"/>
        <child link="laser_link"/>
    </joint>

<!-- /////////////////////////////////////    holder    ///////////////////////////////////////////// -->
    <link name="holder_link">
		<visual>
			<origin xyz=" 0 0 0 " rpy="0 0 0" />
			<geometry>
				<cylinder length="0.05" radius="0.01"/>
			</geometry>
			<material name="Yellow"/>
		</visual>
    </link>

    <joint name="holder_joint" type="fixed">
        <origin xyz="0.09 0 0.15" rpy="0 0 0"/>
        <parent link="base_link"/>
        <child link="holder_link"/>
    </joint>

<!-- /////////////////////////////////////    Back Wheels   ///////////////////////////////////////////// -->
  <link name="back_leftwheel">
    <visual>
    <origin xyz="0 0.0 0.0" rpy="1.5707 0 0"/>
      <geometry>
        <cylinder length="0.04" radius="0.05"/>
      </geometry>
      <material name="Black"/>

    </visual>
  </link>
 
  <joint name="back_leftwheel_joint" type="continuous">
    <origin xyz="-0.09 0.0915 0.0" rpy="0 0 0"/>
    <parent link="base_link"/>
     <child link="back_leftwheel"/>
     <axis xyz="0 1 0"/>
  </joint>

  <link name="back_rightwheel">
    <visual>
    <origin xyz="0 0.0 0.0" rpy="1.5707 0 0"/>
      <geometry>
        <cylinder length="0.04" radius="0.05"/>
      </geometry>
      <material name="Black"/>

    </visual>
  </link>
 
  <joint name="back_rightwheel_joint" type="continuous">
    <origin xyz="-0.09 -0.0915 0.0" rpy="0 0 0"/>
    <parent link="base_link"/>
     <child link="back_rightwheel"/>
     <axis xyz="0 1 0"/>
  </joint>



</robot>
